master_addr is only used for static rdzv_backend and when rdzv_endpoint is not specified.
Setting ds_accelerator to cuda (auto detect)
11/29/2023 14:21:14 - WARNING - __main__ - Process rank: 0, device: cuda:0, n_gpu: 1distributed training: True, 16-bits training: False
11/29/2023 14:21:14 - INFO - __main__ - Training/evaluation parameters Seq2SeqTrainingArguments(
_n_gpu=1,
adafactor=False,
adam_beta1=0.9,
adam_beta2=0.999,
adam_epsilon=1e-08,
auto_find_batch_size=False,
bf16=False,
bf16_full_eval=False,
data_seed=None,
dataloader_drop_last=False,
dataloader_num_workers=0,
dataloader_pin_memory=True,
ddp_backend=None,
ddp_bucket_cap_mb=None,
ddp_find_unused_parameters=None,
ddp_timeout=1800,
debug=[],
deepspeed=None,
disable_tqdm=False,
do_eval=False,
do_predict=False,
do_train=False,
eval_accumulation_steps=None,
eval_delay=0,
eval_steps=None,
evaluation_strategy=no,
fp16=False,
fp16_backend=auto,
fp16_full_eval=False,
fp16_opt_level=O1,
fsdp=[],
fsdp_config={'fsdp_min_num_params': 0, 'xla': False, 'xla_fsdp_grad_ckpt': False},
fsdp_min_num_params=0,
fsdp_transformer_layer_cls_to_wrap=None,
full_determinism=False,
generation_config=None,
generation_max_length=None,
generation_num_beams=None,
gradient_accumulation_steps=16,
gradient_checkpointing=False,
greater_is_better=None,
group_by_length=False,
half_precision_backend=auto,
hub_model_id=None,
hub_private_repo=False,
hub_strategy=every_save,
hub_token=<HUB_TOKEN>,
ignore_data_skip=False,
include_inputs_for_metrics=False,
jit_mode_eval=False,
label_names=None,
label_smoothing_factor=0.0,
learning_rate=0.02,
length_column_name=length,
load_best_model_at_end=False,
local_rank=0,
log_level=passive,
log_level_replica=warning,
log_on_each_node=True,
logging_dir=output/tool_alpaca_pt-20231129-142111-128-2e-2/runs/Nov29_14-21-14_freeview-Precision-3650-Tower,
logging_first_step=False,
logging_nan_inf_filter=True,
logging_steps=1.0,
logging_strategy=steps,
lr_scheduler_type=linear,
max_grad_norm=1.0,
max_steps=1000,
metric_for_best_model=None,
mp_parameters=,
no_cuda=False,
num_train_epochs=3.0,
optim=adamw_hf,
optim_args=None,
output_dir=output/tool_alpaca_pt-20231129-142111-128-2e-2,
overwrite_output_dir=False,
past_index=-1,
per_device_eval_batch_size=8,
per_device_train_batch_size=1,
predict_with_generate=False,
prediction_loss_only=False,
push_to_hub=False,
push_to_hub_model_id=None,
push_to_hub_organization=None,
push_to_hub_token=<PUSH_TO_HUB_TOKEN>,
ray_scope=last,
remove_unused_columns=True,
report_to=['tensorboard'],
resume_from_checkpoint=None,
run_name=output/tool_alpaca_pt-20231129-142111-128-2e-2,
save_on_each_node=False,
save_safetensors=False,
save_steps=500,
save_strategy=steps,
save_total_limit=None,
seed=42,
sharded_ddp=[],
skip_memory_metrics=True,
sortish_sampler=False,
tf32=None,
torch_compile=False,
torch_compile_backend=None,
torch_compile_mode=None,
torchdynamo=None,
tpu_metrics_debug=False,
tpu_num_cores=None,
use_ipex=False,
use_legacy_prediction_loop=False,
use_mps_device=False,
warmup_ratio=0.0,
warmup_steps=0,
weight_decay=0.0,
xpu_backend=None,
)
Traceback (most recent call last):
  File "/home/freeview/.local/lib/python3.10/site-packages/transformers/configuration_utils.py", line 629, in _get_config_dict
    resolved_config_file = cached_file(
  File "/home/freeview/.local/lib/python3.10/site-packages/transformers/utils/hub.py", line 417, in cached_file
    resolved_file = hf_hub_download(
  File "/home/freeview/.local/lib/python3.10/site-packages/huggingface_hub/utils/_validators.py", line 110, in _inner_fn
    validate_repo_id(arg_value)
  File "/home/freeview/.local/lib/python3.10/site-packages/huggingface_hub/utils/_validators.py", line 158, in validate_repo_id
    raise HFValidationError(
huggingface_hub.utils._validators.HFValidationError: Repo id must be in the form 'repo_name' or 'namespace/repo_name': '/AICG/chatglm3-6b'. Use `repo_type` argument if needed.

During handling of the above exception, another exception occurred:

Traceback (most recent call last):
  File "/home/freeview/AICG/ChatGLM3/finetune_chatmodel_demo/finetune.py", line 165, in <module>
    main()
  File "/home/freeview/AICG/ChatGLM3/finetune_chatmodel_demo/finetune.py", line 84, in main
    config = AutoConfig.from_pretrained(model_args.model_name_or_path, trust_remote_code=True)
  File "/home/freeview/.local/lib/python3.10/site-packages/transformers/models/auto/configuration_auto.py", line 944, in from_pretrained
    config_dict, unused_kwargs = PretrainedConfig.get_config_dict(pretrained_model_name_or_path, **kwargs)
  File "/home/freeview/.local/lib/python3.10/site-packages/transformers/configuration_utils.py", line 574, in get_config_dict
    config_dict, kwargs = cls._get_config_dict(pretrained_model_name_or_path, **kwargs)
  File "/home/freeview/.local/lib/python3.10/site-packages/transformers/configuration_utils.py", line 650, in _get_config_dict
    raise EnvironmentError(
OSError: Can't load the configuration of '/AICG/chatglm3-6b'. If you were trying to load it from 'https://huggingface.co/models', make sure you don't have a local directory with the same name. Otherwise, make sure '/AICG/chatglm3-6b' is the correct path to a directory containing a config.json file
ERROR:torch.distributed.elastic.multiprocessing.api:failed (exitcode: 1) local_rank: 0 (pid: 247643) of binary: /usr/bin/python3
Traceback (most recent call last):
  File "/home/freeview/.local/bin/torchrun", line 8, in <module>
    sys.exit(main())
  File "/home/freeview/.local/lib/python3.10/site-packages/torch/distributed/elastic/multiprocessing/errors/__init__.py", line 346, in wrapper
    return f(*args, **kwargs)
  File "/home/freeview/.local/lib/python3.10/site-packages/torch/distributed/run.py", line 794, in main
    run(args)
  File "/home/freeview/.local/lib/python3.10/site-packages/torch/distributed/run.py", line 785, in run
    elastic_launch(
  File "/home/freeview/.local/lib/python3.10/site-packages/torch/distributed/launcher/api.py", line 134, in __call__
    return launch_agent(self._config, self._entrypoint, list(args))
  File "/home/freeview/.local/lib/python3.10/site-packages/torch/distributed/launcher/api.py", line 250, in launch_agent
    raise ChildFailedError(
torch.distributed.elastic.multiprocessing.errors.ChildFailedError: 
============================================================
finetune.py FAILED
------------------------------------------------------------
Failures:
  <NO_OTHER_FAILURES>
------------------------------------------------------------
Root Cause (first observed failure):
[0]:
  time      : 2023-11-29_14:21:17
  host      : freeview-Precision-3650-Tower
  rank      : 0 (local_rank: 0)
  exitcode  : 1 (pid: 247643)
  error_file: <N/A>
  traceback : To enable traceback see: https://pytorch.org/docs/stable/elastic/errors.html
============================================================
